[RequestForInformationAgent ERROR] 2025-10-25T00:33:01.803923
Traceback (most recent call last):
  File "/workspaces/KotP_Team12/src/InvestigationAgent.py", line 260, in _handle_request_async
    info_result = await info_agent.handle_request(context)
                  ^^^^^^^^^^^^^^^^^^^^^^^^^^^^^^^^^^^^^^^^
  File "/workspaces/KotP_Team12/src/RequestForInformationAgent.py", line 91, in handle_request
    return await self._handle_request_async(context)
           ^^^^^^^^^^^^^^^^^^^^^^^^^^^^^^^^^^^^^^^^^
  File "/workspaces/KotP_Team12/src/RequestForInformationAgent.py", line 160, in _handle_request_async
    run = self.project_client.agents.runs.submit_tool_outputs(
          ^^^^^^^^^^^^^^^^^^^^^^^^^^^^^^^^^^^^^^^^^^^^^^^^^^^^
  File "/home/codespace/.local/lib/python3.12/site-packages/azure/core/tracing/decorator.py", line 119, in wrapper_use_tracer
    return func(*args, **kwargs)
           ^^^^^^^^^^^^^^^^^^^^^
  File "/home/codespace/.local/lib/python3.12/site-packages/azure/ai/agents/operations/_patch.py", line 1168, in submit_tool_outputs
    response = super().submit_tool_outputs(
               ^^^^^^^^^^^^^^^^^^^^^^^^^^^^
  File "/home/codespace/.local/lib/python3.12/site-packages/azure/core/tracing/decorator.py", line 119, in wrapper_use_tracer
    return func(*args, **kwargs)
           ^^^^^^^^^^^^^^^^^^^^^
  File "/home/codespace/.local/lib/python3.12/site-packages/azure/ai/agents/operations/_operations.py", line 3128, in submit_tool_outputs
    raise HttpResponseError(response=response, model=error)
azure.core.exceptions.HttpResponseError: (invalid_type) Invalid type for 'tool_outputs[0].output': expected a string, but got an object instead.
Code: invalid_type
Message: Invalid type for 'tool_outputs[0].output': expected a string, but got an object instead.

[RequestForInformationAgent ERROR] 2025-10-25T00:35:46.821261
Traceback (most recent call last):
  File "/workspaces/KotP_Team12/src/InvestigationAgent.py", line 260, in _handle_request_async
    info_result = await info_agent.handle_request(context)
                  ^^^^^^^^^^^^^^^^^^^^^^^^^^^^^^^^^^^^^^^^
  File "/workspaces/KotP_Team12/src/RequestForInformationAgent.py", line 91, in handle_request
    return await self._handle_request_async(context)
           ^^^^^^^^^^^^^^^^^^^^^^^^^^^^^^^^^^^^^^^^^
  File "/workspaces/KotP_Team12/src/RequestForInformationAgent.py", line 162, in _handle_request_async
    run = self.project_client.agents.runs.submit_tool_outputs(
          ^^^^^^^^^^^^^^^^^^^^^^^^^^^^^^^^^^^^^^^^^^^^^^^^^^^^
  File "/home/codespace/.local/lib/python3.12/site-packages/azure/core/tracing/decorator.py", line 119, in wrapper_use_tracer
    return func(*args, **kwargs)
           ^^^^^^^^^^^^^^^^^^^^^
  File "/home/codespace/.local/lib/python3.12/site-packages/azure/ai/agents/operations/_patch.py", line 1168, in submit_tool_outputs
    response = super().submit_tool_outputs(
               ^^^^^^^^^^^^^^^^^^^^^^^^^^^^
  File "/home/codespace/.local/lib/python3.12/site-packages/azure/core/tracing/decorator.py", line 119, in wrapper_use_tracer
    return func(*args, **kwargs)
           ^^^^^^^^^^^^^^^^^^^^^
  File "/home/codespace/.local/lib/python3.12/site-packages/azure/ai/agents/operations/_operations.py", line 3128, in submit_tool_outputs
    raise HttpResponseError(response=response, model=error)
azure.core.exceptions.HttpResponseError: (None) Duplicate call_ids submitted: ['call_IqYp5nsu0mLcy7CXNOeZxiua', 'call_IqYp5nsu0mLcy7CXNOeZxiua', 'call_IqYp5nsu0mLcy7CXNOeZxiua']
Code: None
Message: Duplicate call_ids submitted: ['call_IqYp5nsu0mLcy7CXNOeZxiua', 'call_IqYp5nsu0mLcy7CXNOeZxiua', 'call_IqYp5nsu0mLcy7CXNOeZxiua']

